Workbook

Sheet DISPENDIO Geral Empresa
A2: PROJETO: BIO CAROÇO - Desenvolvimento de um Sistema de Gestão Inteligente de Coletas
A3: EMPRESA: LC Indústria e Comercio de Frutas LTDA.
A5: CONTROLE - DISPÊNDIOS POR RECURSO
A6: ORIGINAL - versão atualizada dia 05/10/2026
A7: PLANO DE TRABALHO CONSOLIDADO EMPRESA
A8: DISPÊNDIOS | B8: VALOR (R$) | C8: %
A9: I - programas de computador, máquinas, equipamentos, aparelhos e instrumentos, seus acessórios, sobressalentes e ferramentas, e serviços de instalação dessas máquinas e equipamentos utilizados na execução do projeto; | B9: ='Fluxo de Caixa'!L5 -> 0 | C9: =IF($B$24=0,0,B9/$B$24) -> 0
A10: II - aquisição, implantação, ampliação ou modernização de infraestrutura física e de laboratórios de pesquisa, desenvolvimento e inovação e de ICTs; | B10: ='Fluxo de Caixa'!L6 -> 0 | C10: =IF($B$24=0,0,B10/$B$24) -> 0
A11: III - RH direto | B11: ='Fluxo de Caixa'!L7 -> 134250 | C11: =IF($B$24=0,0,B11/$B$24) -> 0.90808852
A12: IV - RH indireto | B12: ='Fluxo de Caixa'!L8 -> 8400 | C12: =IF($B$24=0,0,B12/$B$24) -> 0.056818947
A13: V - Serviços Técnicos de Terceiros; | B13: ='Fluxo de Caixa'!L9 -> 0 | C13: =IF($B$24=0,0,B13/$B$24) -> 0
A14: VI - Mat. Consumo | B14: ='Fluxo de Caixa'!L10 -> 0 | C14: =IF($B$24=0,0,B14/$B$24) -> 0
A15: Total Dispêndios (I a VI) | B15: =SUM(B9:B14) -> 142650 | C15: =IF($B$24=0,0,B15/$B$24) -> 0.96490747
A16: VII - Outros dispêndios correlatos às atividades de pesquisa, desenvolvimento e inovação. | B16: =SUM(B17:B20) -> 5188.01 | C16: =IF($B$24=0,0,B16/$B$24) -> 0.035092531
A17: Publicações e Treinamentos | B17: ='Fluxo de Caixa'!L13 -> 0 | C17: =IF($B$24=0,0,B17/$B$24) -> 0
A18: Viagens e diárias | B18: ='Fluxo de Caixa'!L14 -> 0 | C18: =IF($B$24=0,0,B18/$B$24) -> 0
A19: ISS | B19: ='Fluxo de Caixa'!L15 -> 4125 | C19: =IF($B$24=0,0,B19/$B$24) -> 0.027902161
A20: Outros(Aluguel, Internet, Telefonia, Impostos Etc) | B20: ='Fluxo de Caixa'!L16 -> 1063.01 | C20: =IF($B$24=0,0,B20/$B$24) -> 0.0071903701
A21: Total Dispêndios (I a VII) | B21: =B16+B15 -> 147838.01 | C21: =IF($B$24=0,0,B21/$B$24) -> 1
A22: DOA (Despesas operacionais e Administrativas) | B22: ='Fluxo de Caixa'!L19 -> 0 | C22: =IF($B$24=0,0,B22/$B$24) -> 0
A23: Constituição de Reserva | B23: ='Fluxo de Caixa'!L20 -> 0 | C23: =IF($B$24=0,0,B23/$B$24) -> 0
A24: TOTAL | B24: =B21+B22+B23 -> 147838.01 | C24: =C21+C22+C23 -> 1

Sheet Fluxo de Caixa
A2: PLANEJAMENTO - FLUXO DE CAIXA DO PROJETO - EMPRESA
A3: PLANILHA DE DESPÊNDIOS - CONFORME PLANO DE TRABALHO PROPOSTO | D3: 2026 | J3: 2027 | L3: Total Executado | M3: % Executado
D4: JULHO | E4: AGOSTO | F4: SETEMBRO | G4: OUTUBRO | H4: NOVEMBRO | I4: DEZEMBRO | J4: JANEIRO | K4: FEVEREIRO | L4: ANO BASE 2026 (R$) | M4: 2026 (%)
A5: I - programas de computador, máquinas, equipamentos, aparelhos e instrumentos, seus acessórios, e serviços de instalação dessas máquinas e equipamentos utilizados na execução do projeto; | B5: 0 | C5: =IF(OR(B5=0,B5=""),0,B5/$B$21) -> 0 | D5: 0 | E5: 0 | F5: 0 | L5: =SUM(D5:K5) -> 0 | M5: =IF(L5=0,0,L5/$L$21) -> 0
A6: II - aquisição, implantação, ampliação ou modernização de infraestrutura física e de laboratórios de pesquisa, desenvolvimento e inovação e de ICTs; | B6: 0 | C6: =IF(OR(B6=0,B6=""),0,B6/$B$21) -> 0 | D6: 0 | E6: 0 | F6: 0 | L6: =SUM(D6:K6) -> 0 | M6: =IF(L6=0,0,L6/$L$21) -> 0
A7: III - RH direto | B7: 458000 | C7: =IF(OR(B7=0,B7=""),"",B7/$B$21) -> 0.80492091 | D7: 12000 | E7: 64125 | F7: 58125 | L7: =SUM(D7:K7) -> 134250 | M7: =IF(L7=0,0,L7/$L$21) -> 0.90808852
A8: IV - RH indireto | B8: 22400 | C8: =IF(OR(B8=0,B8=""),"",B8/$B$21) -> 0.039367311 | D8: 2800 | E8: 2800 | F8: 2800 | L8: =SUM(D8:K8) -> 8400 | M8: =IF(L8=0,0,L8/$L$21) -> 0.056818947
A9: V - Serviços Técnicos de Terceiros; | B9: 8937 | C9: =IF(OR(B9=0,B9=""),"",B9/$B$21) -> 0.015706503 | D9: 0 | E9: 0 | F9: 0 | L9: =SUM(D9:K9) -> 0 | M9: =IF(L9=0,0,L9/$L$21) -> 0
A10: VI - Materiais de Consumo | B10: 0 | C10: =IF(OR(B10=0,B10=""),0,B10/$B$21) -> 0 | D10: 0 | E10: 0 | F10: 0 | L10: =SUM(D10:K10) -> 0 | M10: =IF(L10=0,0,L10/$L$21) -> 0
A11: Total Dispêndios (I a VI) | B11: =SUM(B5:B10) -> 489337 | C11: =IF(OR(B11=0,B11=""),0,B11/$B$21) -> 0.85999473 | D11: =SUM(D5:D10) -> 14800 | E11: =SUM(E5:E10) -> 66925 | F11: =SUM(F5:F10) -> 60925 | G11: =SUM(G5:G10) -> 0 | H11: =SUM(H5:H10) -> 0 | I11: =SUM(I5:I10) -> 0 | J11: =SUM(J5:J10) -> 0 | K11: =SUM(K5:K10) -> 0 | L11: =SUM(D11:K11) -> 142650 | M11: =IF(L11=0,0,L11/$L$21) -> 0.96490747
A12: VII - Outros dispêndios correlatos às atividades de pesquisa, desenvolvimento e inovação. | B12: =SUM(B13:B16) -> 7400 | C12: =IF(OR(B12=0,B12=""),0,B12/$B$21) -> 0.013005272 | D12: =SUM(D13:D16) -> 4234.28 | E12: =SUM(E13:E16) -> 438.4 | F12: =SUM(F13:F16) -> 515.33 | G12: =SUM(G13:G16) -> 0 | H12: =SUM(H13:H16) -> 0 | I12: =SUM(I13:I16) -> 0 | J12: =SUM(J13:J16) -> 0 | K12: =SUM(K13:K16) -> 0 | L12: =SUM(D12:K12) -> 5188.01 | M12: =IF(L12=0,0,L12/$L$21) -> 0.035092531
A13: Treinamentos; | B13: 0 | C13: =IF(OR(B13=0,B13=""),0,B13/$B$21) -> 0 | D13: 0 | E13: 0 | F13: 0 | L13: =SUM(D13:K13) -> 0 | M13: =IF(L13=0,0,L13/$L$21) -> 0
A14: Viagens; | B14: 0 | C14: =IF(OR(B14=0,B14=""),0,B14/$B$21) -> 0 | D14: 0 | E14: 0 | F14: 0 | L14: =SUM(D14:K14) -> 0 | M14: =IF(L14=0,0,L14/$L$21) -> 0
A15: ISS | B15: 5500 | C15: =IF(OR(B15=0,B15=""),"",B15/$B$21) -> 0.0096660808 | D15: 4125 | E15: 0 | F15: 0 | L15: =SUM(D15:K15) -> 4125 | M15: =IF(L15=0,0,L15/$L$21) -> 0.027902161
A16: Outros (Aluguel, Internet, Telefonia, Impostos, etc.); | B16: 1900 | C16: =IF(OR(B16=0,B16=""),"",B16/$B$21) -> 0.0033391916 | D16: 109.28 | E16: 438.4 | F16: 515.33 | L16: =SUM(D16:K16) -> 1063.01 | M16: =IF(L16=0,0,L16/$L$21) -> 0.0071903701
A17: Total Dispêndios (I a VII) | B17: =SUM(B11,B12) -> 496737 | C17: =IF(OR(B17=0,B17=""),0,B17/$B$21) -> 0.873 | D17: =SUM(D11:D12) -> 19034.28 | E17: =SUM(E11:E12) -> 67363.4 | F17: =SUM(F11:F12) -> 61440.33 | G17: =SUM(G11:G12) -> 0 | H17: =SUM(H11:H12) -> 0 | I17: =SUM(I11:I12) -> 0 | J17: =SUM(J11:J12) -> 0 | K17: =SUM(K11:K12) -> 0 | L17: =SUM(D17:K17) -> 147838.01 | M17: =IF(L17=0,0,L17/$L$21) -> 1
A18: VII - Total DOAS e Fundo de Reserva | B18: =SUM(B19:B20) -> 72263 | C18: =IF(OR(B18=0,B18=""),0,B18/$B$21) -> 0.127 | D18: =SUM(D19:D20) -> 0 | E18: =SUM(E19:E20) -> 0 | F18: =SUM(F19:F20) -> 0 | G18: =SUM(G19:G20) -> 0 | H18: =SUM(H19:H20) -> 0 | I18: =SUM(I19:I20) -> 0 | J18: =SUM(J19:J20) -> 0 | K18: =SUM(K19:K20) -> 0 | L18: =SUM(D18:K18) -> 0 | M18: =IF(L18=0,0,L18/$L$21) -> 0
A19: DOA (Despesas operacionais e Administrativas) | B19: 60883 | C19: =IF(OR(B19=0,B19=""),"",B19/$B$21) -> 0.107 | D19: 0 | E19: 0 | F19: 0 | L19: =SUM(D19:K19) -> 0 | M19: =IF(L19=0,0,L19/$L$21) -> 0
A20: Constituição de Reserva | B20: 11380 | C20: =IF(OR(B20=0,B20=""),"",B20/$B$21) -> 0.02 | D20: 0 | E20: 0 | F20: 0 | L20: =SUM(D20:K20) -> 0 | M20: =IF(L20=0,0,L20/$L$21) -> 0
A21: Total | B21: =B17+B18 -> 569000 | C21: =C17+C18 -> 1 | D21: =D17+D18 -> 19034.28 | E21: =E17+E18 -> 67363.4 | F21: =F17+F18 -> 61440.33 | G21: =G17+G18 -> 0 | H21: =H17+H18 -> 0 | I21: =I17+I18 -> 0 | ... L21: =L17+L18 -> 147838.01 | M21: =IF(B21=0,0,$L$21/$B$21) -> 0.25982076

Sheet Cronograma Desembolso
A1: DESEMBOLSO
A2: CRONOGRAMA DE DESEMBOLSO - Atual (EMPRESA)
A3: Item | B3: Meses | C3: Parcela | D3: Previsto/Bruto | E3: Realizado/NF | F3: NF | G3: Data NF | H3: Unidade | I3: OBS | J3: Oficio | K3: Ano Base
A4: I - Equipamentos e/ou Materiais Permanentes | B4: - | C4: - | D4: 0 | E4: 0 | F4: - | G4: - | H4: - | I4: - | J4: - | K4: 2026
A5: II- Implantação, ampliação ou modernização | B5: - | C5: - | D5: 0 | E5: 0 | F5: - | G5: - | H5: - | I5: - | J5: -
A6: III - RH direto | D6: =D7+D8+D9+D10+D11+D12+D13+D14+D15+D16+D17+D18 -> 458000 | E6: =E7+E8+E9+E10+E11+E12+E13+E14+E15+E16+E17+E18 -> 134250 | F6: - | G6: - | H6: - | I6: - | J6: -
A7: Coordenador | B7: 9 | C7: 12000 | D7: =B7*C7 -> 108000 | E7: =VLOOKUP(A7,'Pagamento RH'!$C$7:$Q$18,15,FALSE) -> 36000
A8: Cientista de Dados | B8: 9 | C8: 7000 | D8: =B8*C8 -> 63000 | E8: =VLOOKUP(A8,'Pagamento RH'!$C$7:$Q$18,15,FALSE) -> 21000
A9: Engenheiro de Software | B9: 9 | C9: 5000 | D9: =B9*C9 -> 45000 | E9: =VLOOKUP(A9,'Pagamento RH'!$C$7:$Q$18,15,FALSE) -> 10000
A10: Analista Integrador | B10: 9 | C10: 5000 | D10: =B10*C10 -> 45000 | E10: =VLOOKUP(A10,'Pagamento RH'!$C$7:$Q$18,15,FALSE) -> 10000
A11: Analista de Teste | B11: 9 | C11: 5000 | D11: =B11*C11 -> 45000 | E11: =VLOOKUP(A11,'Pagamento RH'!$C$7:$Q$18,15,FALSE) -> 15000
A12: Desenvolvedor Full Stack | B12: 9 | C12: 5000 | D12: =B12*C12 -> 45000 | E12: =VLOOKUP(A12,'Pagamento RH'!$C$7:$Q$18,15,FALSE) -> 10000
A13: Aluno Graduação - (AI) | B13: 9 | C13: 2000 | D13: =B13*C13 -> 18000 | E13: =VLOOKUP(A13,'Pagamento RH'!$C$7:$Q$18,15,FALSE) -> 6000
A14: Aluno Graduação (Frontend) | B14: 8 | C14: 2125 | D14: =B14*C14 -> 17000 | E14: =VLOOKUP(A14,'Pagamento RH'!$C$7:$Q$18,15,FALSE) -> 4250
A15: Aluno Graduação - (Frontend) | B15: 9 | C15: 2000 | D15: =B15*C15 -> 18000 | E15: =VLOOKUP(A15,'Pagamento RH'!$C$7:$Q$18,15,FALSE) -> 6000
A16: Aluno Graduação (Backend) | B16: 9 | C16: 2000 | D16: =B16*C16 -> 18000 | E16: =VLOOKUP(A16,'Pagamento RH'!$C$7:$Q$18,15,FALSE) -> 4000
A17: Aluno Graduação - (Backend) | B17: 9 | C17: 2000 | D17: =B17*C17 -> 18000 | E17: =VLOOKUP(A17,'Pagamento RH'!$C$7:$Q$18,15,FALSE) -> 6000
A18: Aluno Graduação - (QA) | B18: 9 | C18: 2000 | D18: =B18*C18 -> 18000 | E18: =VLOOKUP(A18,'Pagamento RH'!$C$7:$Q$18,15,FALSE) -> 6000
A19: III - RH indireto | D19: =D20 -> 22400 | E19: =E20 -> 8400
A20: Auxiliar Administrativo | B20: 8 | C20: 2800 | D20: =B20*C20 -> 22400 | E20: =VLOOKUP(A20,'Pagamento RH'!C26:Q26,15,FALSE) -> 8400
A21: IV - Serviços Técnicos de Terceiros | D21: =D22+D23 -> 8937 | E21: =E22+E23 -> 0
A22: Computação em Nuvem | B22: 9 | C22: 900 | D22: =B22*C22 -> 8100 | E22: 0
A23: Computação em Nuvem | B23: 9 | C23: 93 | D23: =B23*C23 -> 837 | E23: 0
A24: V - Mat. Consumo | D24: 0 | E24: 0
A25: VI - Outros Correlatos (rateio de Aluguel, Internet, Telefonia) | D25: =D26+D27+D29+D28 -> 1900
A26: Treinamentos | D26: 0 | E26: 0
A27: Viagens | D27: 0 | E27: 0
A28: Tarifas Bancárias | B28: 1 | C28: 1000 | D28: =B28*C28 -> 1000
A29: Outros(Aluguel, Internet, Telefonia, Impostos Etc) | B29: 9 | C29: 100 | D29: =B29*C29 -> 900 | E29: 0
A30: DOA (Despesas operacionais e Administrativas) | B30: 1 | C30: 60883 | D30: =B30*C30 -> 60883 | E30: 0
A31: Constituição de Reserva | B31: 1 | C31: 11380 | D31: =B31*C31 -> 11380 | E31: 0
A32: ISS | B32: 1 | C32: 5500 | D32: =C32*B32 -> 5500 | E32: 0
A33: Total | D33: =D4+D5+D6+D19+D21+D24+D25+D30+D31+D32 -> 569000 | E33: =E4+E5+E6+E19+E21+E24+E25+E30+E31+E32 -> 142650
A37: DESEMBOLSO - EMBRAPII
A38: CRONOGRAMA DE DESEMBOLSO - Atual (EMBRAPII)
A39: Item | B39: Meses | C39: Parcela | D39: Previsto/Bruto | E39: Realizado/Bruto | F39: Rendimento
A40: 1 | B40: Junho | C40: 01/02 | D40: 103000 | E40: 103000 | F40: 0
A41: 2 | B41: Julho | D41: 0 | E41: 0 | F41: 0
A42: 3 | B42: Agosto | D42: 0 | E42: 0 | F42: 0
A43: 4 | B43: Setembro | D43: 0 | E43: 0 | F43: 0
...

Sheet Pagamento RH
A2: PAGAMENTOS REALIZADOS - EMPRESA
A3: ITEM | B3: Colaborador | C3: Função | D3: Parcelas | E3: Valor da Bolsas | F3: Valor Total | G3: CH - Mensal | H3: 46174 | I3: 46204 | J3: 46235 | K3: 46266 | L3: 46296 | M3: 46327 | N3: 46357 | O3: 46388 | P3: 46419 | Q3: Valores Pagos | R3: Saldo
H4: Parcela 1/9 | I4: Parcela 2/9 | J4: Parcela 3/9 | K4: Parcela 4/9 | L4: Parcela 5/9 | M4: Parcela 6/9 | N4: Parcela 7/9 | O4: Parcela 8/9 | P4: Parcela 9/9
H5: ANO BASE 2026
A6: RH - DIRETO
A7: 1 | B7: Wenndisson da Silva Souza | C7: Coordenador | D7: 9 | E7: 12000 | F7: =E7*D7 -> 108000 | G7: 40 | H7: 12000 | I7: 12000 | J7: 12000 | Q7: =SUM(H7:P7) -> 36000 | R7: =F7-Q7 -> 72000
A8: 2 | B8: Eduardo Palhares Júnior | C8: Cientista de Dados | D8: 9 | E8: 7000 | F8: =E8*D8 -> 63000 | G8: 40 | H8: 7000 | I8: 7000 | J8: 7000 | Q8: =SUM(H8:P8) -> 21000 | R8: =F8-Q8 -> 42000
A9: 3 | B9: Gabriel Clavila Soares | C9: Engenheiro de Software | D9: 9 | E9: 5000 | F9: =E9*D9 -> 45000 | G9: 40 | H9: 5000 | I9: 5000 | Q9: =SUM(H9:P9) -> 10000 | R9: =F9-Q9 -> 35000
A10: 4 | B10: Liane de Oliveira Calais Sobreira | C10: Analista Integrador | D10: 9 | E10: 5000 | F10: =E10*D10 -> 45000 | G10: 40 | H10: 5000 | I10: 5000 | Q10: =SUM(H10:P10) -> 10000 | R10: =F10-Q10 -> 35000
A11: 5 | B11: Gabriel Silveira Alencar | C11: Analista de Teste | D11: 9 | E11: 5000 | F11: =E11*D11 -> 45000 | G11: 40 | H11: 5000 | I11: 5000 | J11: 5000 | Q11: =SUM(H11:P11) -> 15000 | R11: =F11-Q11 -> 30000
A12: 6 | B12: Sandro Haiden Teixeira | C12: Desenvolvedor Full Stack | D12: 9 | E12: 5000 | F12: =E12*D12 -> 45000 | G12: 40 | H12: 5000 | I12: 5000 | Q12: =SUM(H12:P12) -> 10000 | R12: =F12-Q12 -> 35000
A13: 7 | B13: Nobuyuki Andrade Ashibe | C13: Aluno Graduação - (AI) | D13: 9 | E13: 2000 | F13: =E13*D13 -> 18000 | G13: 40 | H13: 2000 | I13: 2000 | J13: 2000 | Q13: =SUM(H13:P13) -> 6000 | R13: =F13-Q13 -> 12000
A14: 8 | B14: Cairo José Nascimento Carneiro | C14: Aluno Graduação (Frontend) | D14: 8 | E14: 2125 | F14: =E14*D14 -> 17000 | G14: 40 | H14: 2125 | I14: 2125 | Q14: =SUM(H14:P14) -> 4250 | R14: =F14-Q14 -> 12750
A15: 9 | B15: Jose Mario Castro de Amaral | C15: Aluno Graduação - (Frontend) | D15: 9 | E15: 2000 | F15: =E15*D15 -> 18000 | G15: 40 | H15: 2000 | I15: 2000 | J15: 2000 | Q15: =SUM(H15:P15) -> 6000 | R15: =F15-Q15 -> 12000
A16: 10 | B16: Bruno Cesar de Souza Falcao | C16: Aluno Graduação - (Backend) | D16: 9 | E16: 2000 | F16: =E16*D16 -> 18000 | G16: 40 | H16: 2000 | I16: 2000 | J16: 2000 | Q16: =SUM(H16:P16) -> 6000 | R16: =F16-Q16 -> 12000
A17: 11 | B17: Rafael Freire Couto da Silva | C17: Aluno Graduação (Backend) | D17: 9 | E17: 2000 | F17: =E17*D17 -> 18000 | G17: 40 | H17: 2000 | I17: 2000 | Q17: =SUM(H17:P17) -> 4000 | R17: =F17-Q17 -> 14000
A18: 12 | B18: Gabriel Nogueira de Lima | C18: Aluno Graduação - (QA) | D18: 9 | E18: 2000 | F18: =E18*D18 -> 18000 | G18: 40 | H18: 2000 | I18: 2000 | J18: 2000 | Q18: =SUM(H18:P18) -> 6000 | R18: =F18-Q18 -> 12000
A22: TOTAL | E22: =SUM(E7:E18) -> 51125 | F22: =SUM(F7:F18) -> 458000 | H22: =SUM(H7:H18) -> 51125 | I22: =SUM(I7:I18) -> 51125 | J22: =SUM(J7:J18) -> 32000 | K22: =SUM(K7:K18) -> 0 | L22: =SUM(L7:L18) -> 0 | M22: =SUM(M7:M18) -> 0 | N22: =SUM(N7:N18) -> 0 | O22: =SUM(O7:O18) -> 0 | ... R22: =SUM(R7:R18) -> 323750
A25: RH - INDIRETO
A26: 1 | B26: Geziel Sena Colares | C26: Auxiliar Administrativo | D26: 8 | E26: 2800 | F26: =E26*D26 -> 22400 | G26: 20 | H26: 2800 | I26: 2800 | J26: 2800 | Q26: =SUM(H26:P26) -> 8400 | R26: =F26-Q26 -> 14000
A28: TOTAL | E28: =E26 -> 2800 | F28: =F26 -> 22400 | H28: =H26 -> 2800 | I28: =I26 -> 2800 | J28: =J26 -> 2800 | K28: =K26 -> 0 | L28: =L26 -> 0 | M28: =M26 -> 0 | N28: =N26 -> 0 | O28: =O26 -> 0 | ... R28: =R26 -> 14000

Sheet Controle - Remanejamento
A1: CONTROLE - DISPÊNDIOS
A3: ORIGINAL LC FRUTAS | E3: 1º REMANEJAMENTO | I3: 2º REMANEJAMENTO
A4: DISPÊNDIOS | B4: VALOR (R$) | C4: % | E4: DISPÊNDIOS | F4: VALOR (R$) | G4: % | I4: DISPÊNDIOS | J4: VALOR (R$) | K4: %
A5: I - programas de computador, máquinas, equipamentos, aparelhos e instrumentos, seus acessórios, sobressalentes e ferramentas, e serviços de instalação dessas máquinas e equipamentos utilizados na execução do projeto; | C5: =B5/B21 -> #DIV/0! | E5: I - programas de computador, máquinas, equipamentos, aparelhos e instrumentos, seus acessórios, sobressalentes e ferramentas, e serviços de instalação dessas máquinas e equipamentos utilizados na execução do projeto; | G5: =F5/F21 -> #DIV/0! | I5: I - programas de computador, máquinas, equipamentos, aparelhos e instrumentos, seus acessórios, sobressalentes e ferramentas, e serviços de instalação dessas máquinas e equipamentos utilizados na execução do projeto; | K5: =J5/J21 -> #DIV/0!
A6: II - Obras civis (aquisição, implantação, ampliação ou modernização de infraestrutura física e de laboratórios) | C6: =B6/B21 -> #DIV/0! | E6: II - aquisição, implantação, ampliação ou modernização de infraestrutura física e de laboratórios de pesquisa, desenvolvimento e inovação e de ICTs; | G6: =F6/F21 -> #DIV/0! | I6: II - aquisição, implantação, ampliação ou modernização de infraestrutura física e de laboratórios de pesquisa, desenvolvimento e inovação e de ICTs; | K6: =J6/J21 -> #DIV/0!
A7: III - RH direto | C7: =B7/B21 -> #DIV/0! | E7: III - RH diretos projeto | G7: =F7/F21 -> #DIV/0! | I7: III - RH diretos projeto | K7: =J7/J21 -> #DIV/0!
A8: III - RH indireto | C8: =B8/B21 -> #DIV/0! | E8: III - RH indireto do projeto | G8: =F8/F21 -> #DIV/0! | I8: III - RH indireto do projeto | K8: =J8/J21 -> #DIV/0!
A9: IV - Serviços Técnicos de Terceiros; | B9: 0 | C9: =B9/B21 -> #DIV/0! | E9: IV - Serviços Técnicos de Terceiros; | G9: =F9/F21 -> #DIV/0! | I9: IV - Serviços Técnicos de Terceiros; | K9: =J9/J21 -> #DIV/0!
A10: V - Materiais de Consumo | C10: =B10/B21 -> #DIV/0! | E10: V - Mat. Consumo | F10: 0 | G10: =F10/F21 -> #DIV/0! | I10: V - Mat. Consumo | K10: =J10/J21 -> #DIV/0!
A11: Total Dispêndios (I a V) | B11: =SUM(B5:B10) -> 0 | C11: =B11/B21 -> #DIV/0! | E11: Total Dispêndios (I a V) | F11: =SUM(F5:F10) -> 0 | G11: =F11/F21 -> #DIV/0! | I11: Total Dispêndios (I a V) | J11: =SUM(J5:J10) -> 0 | K11: =J11/J21 -> #DIV/0!
A12: VI - Outros dispêndios correlatos às atividades de pesquisa, desenvolvimento e inovação. | C12: =B12/B21 -> #DIV/0! | E12: VI - Outros dispêndios correlatos às atividades de pesquisa, desenvolvimento e inovação. | F12: =SUM(F13:F15) -> 0 | G12: =F12/F21 -> #DIV/0! | I12: VI - Outros dispêndios correlatos às atividades de pesquisa, desenvolvimento e inovação. | J12: =SUM(J13:J15) -> 0 | K12: =J12/J21 -> #DIV/0!
A13: Treinamentos | B13: 0 | C13: =B13/B21 -> #DIV/0! | E13: Treinamentos | F13: 0 | G13: =F13/F21 -> #DIV/0! | I13: Treinamentos | J13: 0 | K13: =J13/J21 -> #DIV/0!
A14: Viagens | B14: 0 | C14: =B14/B21 -> #DIV/0! | E14: Viagens | F14: 0 | G14: =F14/F21 -> #DIV/0! | I14: Viagens | J14: 0 | K14: =J14/J21 -> #DIV/0!
A15: Outros(Aluguel, Internet, Telefonia, Impostos Etc) | C15: =B15/B21 -> #DIV/0! | E15: Outros(Aluguel, Internet, Telefonia, Impostos Etc) | F15: 0 | G15: =F15/F21 -> #DIV/0! | I15: Outros(Aluguel, Internet, Telefonia, Impostos Etc) | K15: =J15/J21 -> #DIV/0!
A16: Total Dispêndios (I a VI) sem ISS | B16: =SUM(B11:B12) -> 0 | C16: =B16/B21 -> #DIV/0! | E16: Total Dispêndios (I a VI) sem ISS | F16: =SUM(F11:F12) -> 0 | G16: =F16/F21 -> #DIV/0! | I16: Total Dispêndios (I a VI) sem ISS | J16: =SUM(J11:J12) -> 0 | K16: =J16/J21 -> #DIV/0!
A17: DOA (Despesas operacionais e Administrativas) | C17: =B17/B21 -> #DIV/0! | E17: DOA (Despesas operacionais e Administrativas) | G17: =F17/F21 -> #DIV/0! | I17: DOA (Despesas operacionais e Administrativas) | K17: =J17/J21 -> #DIV/0!
A18: Constituição de Reserva | C18: =B18/B21 -> #DIV/0! | E18: Constituição de Reserva | G18: =F18/F21 -> #DIV/0! | I18: Constituição de Reserva | K18: =J18/J21 -> #DIV/0!
A19: TOTAL sem ISS | B19: =SUM(B16:B18) -> 0 | C19: =SUM(C16:C18) -> #DIV/0! | E19: TOTAL sem ISS | F19: =SUM(F16:F18) -> 0 | G19: =SUM(G16:G18) -> #DIV/0! | I19: TOTAL sem ISS | J19: =SUM(J16:J18) -> 0 | K19: =SUM(K16:K18) -> #DIV/0!
A20: TRIBUTAÇÃO ISS (Despesa a ser alocada na rubrica VI - Outros Dispêndios) | C20: 0.05 | E20: TRIBUTAÇÃO ISS (Despesa a ser alocada na rubrica VI - Outros Dispêndios) | G20: 0.05 | I20: TRIBUTAÇÃO ISS (Despesa a ser alocada na rubrica VI - Outros Dispêndios) | K20: 0.05
A21: TOTAL FINAL DO PROJETO | B21: =B19+B20 -> 0 | C21: =C19+C20 -> #DIV/0! | E21: TOTAL FINAL DO PROJETO | F21: =F19+F20 -> 0 | G21: =G19+G20 -> #DIV/0! | I21: TOTAL FINAL DO PROJETO | J21: =J19+J20 -> 0 | K21: =K19+K20 -> #DIV/0!
A25: ORIGINAL EMBRAPII
A26: DISPÊNDIOS | B26: VALOR (R$) | C26: %
A27: I - programas de computador, máquinas, equipamentos, aparelhos e instrumentos, seus acessórios, sobressalentes e ferramentas, e serviços de instalação dessas máquinas e equipamentos utilizados na execução do projeto; | C27: =B27/B42 -> #DIV/0!
A28: II - aquisição, implantação, ampliação ou modernização de infraestrutura física e de laboratórios de pesquisa, desenvolvimento e inovação e de ICTs; | C28: =B28/B42 -> #DIV/0!
A29: III - RH direto | C29: =B29/B42 -> #DIV/0!
A30: III - RH indireto | C30: =B30/B42 -> #DIV/0!
A31: IV - Serviços Técnicos de Terceiros; | C31: =B31/B42 -> #DIV/0!
A32: V - Mat. Consumo | C32: =B32/B42 -> #DIV/0!
A33: Total Dispêndios (I a V) | B33: =SUM(B27:B32) -> 0 | C33: =B33/B42 -> #DIV/0!
A34: VI - Outros dispêndios correlatos às atividades de pesquisa, desenvolvimento e inovação. | C34: =B34/B42 -> #DIV/0!
A35: Treinamentos | C35: =B35/B42 -> #DIV/0!
A36: Viagens | C36: =B36/B42 -> #DIV/0!
A37: ISS | C37: =B37/B42 -> #DIV/0!
A38: Outros(Aluguel, Internet, Telefonia, Impostos Etc) | C38: =B38/B42 -> #DIV/0!
A39: Total Dispêndios (I a VI) sem ISS | C39: =B39/B42 -> #DIV/0!
A40: DOA (Despesas operacionais e Administrativas) | C40: =B40/B42 -> #DIV/0!
A41: Constituição de Reserva | C41: =B41/B42 -> #DIV/0!
A42: TOTAL FINAL DO PROJETO | B42: =B33 -> 0 | C42: =C33 -> #DIV/0!
